2018-05-15 14:06:42,382 ERROR: Exception on /favicon.ico [GET] [in /home/nagianek/.local/lib/python3.6/site-packages/flask/app.py:1560]
Traceback (most recent call last):
  File "/home/nagianek/.local/lib/python3.6/site-packages/flask/app.py", line 1982, in wsgi_app
    response = self.full_dispatch_request()
  File "/home/nagianek/.local/lib/python3.6/site-packages/flask/app.py", line 1614, in full_dispatch_request
    rv = self.handle_user_exception(e)
  File "/home/nagianek/.local/lib/python3.6/site-packages/flask/app.py", line 1517, in handle_user_exception
    reraise(exc_type, exc_value, tb)
  File "/home/nagianek/.local/lib/python3.6/site-packages/flask/_compat.py", line 33, in reraise
    raise value
  File "/home/nagianek/.local/lib/python3.6/site-packages/flask/app.py", line 1610, in full_dispatch_request
    rv = self.preprocess_request()
  File "/home/nagianek/.local/lib/python3.6/site-packages/flask/app.py", line 1831, in preprocess_request
    rv = func()
  File "/home/nagianek/PycharmProjects/Flask-Microblog/venv/app/routes.py", line 123, in before_request
    g.locale = str(get_locale())
  File "/home/nagianek/.local/lib/python3.6/site-packages/flask_babel/__init__.py", line 253, in get_locale
    babel = current_app.extensions['babel']
KeyError: 'babel'
2018-05-15 14:06:42,667 ERROR: Exception on /index [GET] [in /home/nagianek/.local/lib/python3.6/site-packages/flask/app.py:1560]
Traceback (most recent call last):
  File "/home/nagianek/.local/lib/python3.6/site-packages/flask/app.py", line 1982, in wsgi_app
    response = self.full_dispatch_request()
  File "/home/nagianek/.local/lib/python3.6/site-packages/flask/app.py", line 1614, in full_dispatch_request
    rv = self.handle_user_exception(e)
  File "/home/nagianek/.local/lib/python3.6/site-packages/flask/app.py", line 1517, in handle_user_exception
    reraise(exc_type, exc_value, tb)
  File "/home/nagianek/.local/lib/python3.6/site-packages/flask/_compat.py", line 33, in reraise
    raise value
  File "/home/nagianek/.local/lib/python3.6/site-packages/flask/app.py", line 1610, in full_dispatch_request
    rv = self.preprocess_request()
  File "/home/nagianek/.local/lib/python3.6/site-packages/flask/app.py", line 1831, in preprocess_request
    rv = func()
  File "/home/nagianek/PycharmProjects/Flask-Microblog/venv/app/routes.py", line 123, in before_request
    g.locale = str(get_locale())
  File "/home/nagianek/.local/lib/python3.6/site-packages/flask_babel/__init__.py", line 253, in get_locale
    babel = current_app.extensions['babel']
KeyError: 'babel'
2018-05-15 14:06:42,784 ERROR: Exception on /favicon.ico [GET] [in /home/nagianek/.local/lib/python3.6/site-packages/flask/app.py:1560]
Traceback (most recent call last):
  File "/home/nagianek/.local/lib/python3.6/site-packages/flask/app.py", line 1982, in wsgi_app
    response = self.full_dispatch_request()
  File "/home/nagianek/.local/lib/python3.6/site-packages/flask/app.py", line 1614, in full_dispatch_request
    rv = self.handle_user_exception(e)
  File "/home/nagianek/.local/lib/python3.6/site-packages/flask/app.py", line 1517, in handle_user_exception
    reraise(exc_type, exc_value, tb)
  File "/home/nagianek/.local/lib/python3.6/site-packages/flask/_compat.py", line 33, in reraise
    raise value
  File "/home/nagianek/.local/lib/python3.6/site-packages/flask/app.py", line 1610, in full_dispatch_request
    rv = self.preprocess_request()
  File "/home/nagianek/.local/lib/python3.6/site-packages/flask/app.py", line 1831, in preprocess_request
    rv = func()
  File "/home/nagianek/PycharmProjects/Flask-Microblog/venv/app/routes.py", line 123, in before_request
    g.locale = str(get_locale())
  File "/home/nagianek/.local/lib/python3.6/site-packages/flask_babel/__init__.py", line 253, in get_locale
    babel = current_app.extensions['babel']
KeyError: 'babel'
2018-05-15 14:06:43,050 ERROR: Exception on /index [GET] [in /home/nagianek/.local/lib/python3.6/site-packages/flask/app.py:1560]
Traceback (most recent call last):
  File "/home/nagianek/.local/lib/python3.6/site-packages/flask/app.py", line 1982, in wsgi_app
    response = self.full_dispatch_request()
  File "/home/nagianek/.local/lib/python3.6/site-packages/flask/app.py", line 1614, in full_dispatch_request
    rv = self.handle_user_exception(e)
  File "/home/nagianek/.local/lib/python3.6/site-packages/flask/app.py", line 1517, in handle_user_exception
    reraise(exc_type, exc_value, tb)
  File "/home/nagianek/.local/lib/python3.6/site-packages/flask/_compat.py", line 33, in reraise
    raise value
  File "/home/nagianek/.local/lib/python3.6/site-packages/flask/app.py", line 1610, in full_dispatch_request
    rv = self.preprocess_request()
  File "/home/nagianek/.local/lib/python3.6/site-packages/flask/app.py", line 1831, in preprocess_request
    rv = func()
  File "/home/nagianek/PycharmProjects/Flask-Microblog/venv/app/routes.py", line 123, in before_request
    g.locale = str(get_locale())
  File "/home/nagianek/.local/lib/python3.6/site-packages/flask_babel/__init__.py", line 253, in get_locale
    babel = current_app.extensions['babel']
KeyError: 'babel'
2018-05-15 14:06:43,168 ERROR: Exception on /favicon.ico [GET] [in /home/nagianek/.local/lib/python3.6/site-packages/flask/app.py:1560]
Traceback (most recent call last):
  File "/home/nagianek/.local/lib/python3.6/site-packages/flask/app.py", line 1982, in wsgi_app
    response = self.full_dispatch_request()
  File "/home/nagianek/.local/lib/python3.6/site-packages/flask/app.py", line 1614, in full_dispatch_request
    rv = self.handle_user_exception(e)
  File "/home/nagianek/.local/lib/python3.6/site-packages/flask/app.py", line 1517, in handle_user_exception
    reraise(exc_type, exc_value, tb)
  File "/home/nagianek/.local/lib/python3.6/site-packages/flask/_compat.py", line 33, in reraise
    raise value
  File "/home/nagianek/.local/lib/python3.6/site-packages/flask/app.py", line 1610, in full_dispatch_request
    rv = self.preprocess_request()
  File "/home/nagianek/.local/lib/python3.6/site-packages/flask/app.py", line 1831, in preprocess_request
    rv = func()
  File "/home/nagianek/PycharmProjects/Flask-Microblog/venv/app/routes.py", line 123, in before_request
    g.locale = str(get_locale())
  File "/home/nagianek/.local/lib/python3.6/site-packages/flask_babel/__init__.py", line 253, in get_locale
    babel = current_app.extensions['babel']
KeyError: 'babel'
2018-05-15 14:08:57,884 INFO: Microblog startup [in /home/nagianek/PycharmProjects/Flask-Microblog/venv/app/__init__.py:45]
2018-05-15 14:35:45,667 INFO: Microblog startup [in /home/nagianek/PycharmProjects/Flask-Microblog/venv/app/__init__.py:74]
2018-05-15 14:37:45,436 INFO: Microblog startup [in /home/nagianek/PycharmProjects/Flask-Microblog/venv/app/__init__.py:74]
2018-05-15 15:05:04,242 INFO: Microblog startup [in /home/nagianek/PycharmProjects/Flask-Microblog/venv/app/__init__.py:78]
