2018-05-15 14:06:42,382 ERROR: Exception on /favicon.ico [GET] [in /home/nagianek/.local/lib/python3.6/site-packages/flask/app.py:1560]
Traceback (most recent call last):
  File "/home/nagianek/.local/lib/python3.6/site-packages/flask/app.py", line 1982, in wsgi_app
    response = self.full_dispatch_request()
  File "/home/nagianek/.local/lib/python3.6/site-packages/flask/app.py", line 1614, in full_dispatch_request
    rv = self.handle_user_exception(e)
  File "/home/nagianek/.local/lib/python3.6/site-packages/flask/app.py", line 1517, in handle_user_exception
    reraise(exc_type, exc_value, tb)
  File "/home/nagianek/.local/lib/python3.6/site-packages/flask/_compat.py", line 33, in reraise
    raise value
  File "/home/nagianek/.local/lib/python3.6/site-packages/flask/app.py", line 1610, in full_dispatch_request
    rv = self.preprocess_request()
  File "/home/nagianek/.local/lib/python3.6/site-packages/flask/app.py", line 1831, in preprocess_request
    rv = func()
  File "/home/nagianek/PycharmProjects/Flask-Microblog/venv/app/routes.py", line 123, in before_request
    g.locale = str(get_locale())
  File "/home/nagianek/.local/lib/python3.6/site-packages/flask_babel/__init__.py", line 253, in get_locale
    babel = current_app.extensions['babel']
KeyError: 'babel'
2018-05-15 14:06:42,667 ERROR: Exception on /index [GET] [in /home/nagianek/.local/lib/python3.6/site-packages/flask/app.py:1560]
Traceback (most recent call last):
  File "/home/nagianek/.local/lib/python3.6/site-packages/flask/app.py", line 1982, in wsgi_app
    response = self.full_dispatch_request()
  File "/home/nagianek/.local/lib/python3.6/site-packages/flask/app.py", line 1614, in full_dispatch_request
    rv = self.handle_user_exception(e)
  File "/home/nagianek/.local/lib/python3.6/site-packages/flask/app.py", line 1517, in handle_user_exception
    reraise(exc_type, exc_value, tb)
  File "/home/nagianek/.local/lib/python3.6/site-packages/flask/_compat.py", line 33, in reraise
    raise value
  File "/home/nagianek/.local/lib/python3.6/site-packages/flask/app.py", line 1610, in full_dispatch_request
    rv = self.preprocess_request()
  File "/home/nagianek/.local/lib/python3.6/site-packages/flask/app.py", line 1831, in preprocess_request
    rv = func()
  File "/home/nagianek/PycharmProjects/Flask-Microblog/venv/app/routes.py", line 123, in before_request
    g.locale = str(get_locale())
  File "/home/nagianek/.local/lib/python3.6/site-packages/flask_babel/__init__.py", line 253, in get_locale
    babel = current_app.extensions['babel']
KeyError: 'babel'
2018-05-15 14:06:42,784 ERROR: Exception on /favicon.ico [GET] [in /home/nagianek/.local/lib/python3.6/site-packages/flask/app.py:1560]
Traceback (most recent call last):
  File "/home/nagianek/.local/lib/python3.6/site-packages/flask/app.py", line 1982, in wsgi_app
    response = self.full_dispatch_request()
  File "/home/nagianek/.local/lib/python3.6/site-packages/flask/app.py", line 1614, in full_dispatch_request
    rv = self.handle_user_exception(e)
  File "/home/nagianek/.local/lib/python3.6/site-packages/flask/app.py", line 1517, in handle_user_exception
    reraise(exc_type, exc_value, tb)
  File "/home/nagianek/.local/lib/python3.6/site-packages/flask/_compat.py", line 33, in reraise
    raise value
  File "/home/nagianek/.local/lib/python3.6/site-packages/flask/app.py", line 1610, in full_dispatch_request
    rv = self.preprocess_request()
  File "/home/nagianek/.local/lib/python3.6/site-packages/flask/app.py", line 1831, in preprocess_request
    rv = func()
  File "/home/nagianek/PycharmProjects/Flask-Microblog/venv/app/routes.py", line 123, in before_request
    g.locale = str(get_locale())
  File "/home/nagianek/.local/lib/python3.6/site-packages/flask_babel/__init__.py", line 253, in get_locale
    babel = current_app.extensions['babel']
KeyError: 'babel'
2018-05-15 14:06:43,050 ERROR: Exception on /index [GET] [in /home/nagianek/.local/lib/python3.6/site-packages/flask/app.py:1560]
Traceback (most recent call last):
  File "/home/nagianek/.local/lib/python3.6/site-packages/flask/app.py", line 1982, in wsgi_app
    response = self.full_dispatch_request()
  File "/home/nagianek/.local/lib/python3.6/site-packages/flask/app.py", line 1614, in full_dispatch_request
    rv = self.handle_user_exception(e)
  File "/home/nagianek/.local/lib/python3.6/site-packages/flask/app.py", line 1517, in handle_user_exception
    reraise(exc_type, exc_value, tb)
  File "/home/nagianek/.local/lib/python3.6/site-packages/flask/_compat.py", line 33, in reraise
    raise value
  File "/home/nagianek/.local/lib/python3.6/site-packages/flask/app.py", line 1610, in full_dispatch_request
    rv = self.preprocess_request()
  File "/home/nagianek/.local/lib/python3.6/site-packages/flask/app.py", line 1831, in preprocess_request
    rv = func()
  File "/home/nagianek/PycharmProjects/Flask-Microblog/venv/app/routes.py", line 123, in before_request
    g.locale = str(get_locale())
  File "/home/nagianek/.local/lib/python3.6/site-packages/flask_babel/__init__.py", line 253, in get_locale
    babel = current_app.extensions['babel']
KeyError: 'babel'
2018-05-15 14:06:43,168 ERROR: Exception on /favicon.ico [GET] [in /home/nagianek/.local/lib/python3.6/site-packages/flask/app.py:1560]
Traceback (most recent call last):
  File "/home/nagianek/.local/lib/python3.6/site-packages/flask/app.py", line 1982, in wsgi_app
    response = self.full_dispatch_request()
  File "/home/nagianek/.local/lib/python3.6/site-packages/flask/app.py", line 1614, in full_dispatch_request
    rv = self.handle_user_exception(e)
  File "/home/nagianek/.local/lib/python3.6/site-packages/flask/app.py", line 1517, in handle_user_exception
    reraise(exc_type, exc_value, tb)
  File "/home/nagianek/.local/lib/python3.6/site-packages/flask/_compat.py", line 33, in reraise
    raise value
  File "/home/nagianek/.local/lib/python3.6/site-packages/flask/app.py", line 1610, in full_dispatch_request
    rv = self.preprocess_request()
  File "/home/nagianek/.local/lib/python3.6/site-packages/flask/app.py", line 1831, in preprocess_request
    rv = func()
  File "/home/nagianek/PycharmProjects/Flask-Microblog/venv/app/routes.py", line 123, in before_request
    g.locale = str(get_locale())
  File "/home/nagianek/.local/lib/python3.6/site-packages/flask_babel/__init__.py", line 253, in get_locale
    babel = current_app.extensions['babel']
KeyError: 'babel'
2018-05-15 14:08:57,884 INFO: Microblog startup [in /home/nagianek/PycharmProjects/Flask-Microblog/venv/app/__init__.py:45]
2018-05-15 14:35:45,667 INFO: Microblog startup [in /home/nagianek/PycharmProjects/Flask-Microblog/venv/app/__init__.py:74]
2018-05-15 14:37:45,436 INFO: Microblog startup [in /home/nagianek/PycharmProjects/Flask-Microblog/venv/app/__init__.py:74]
2018-05-15 15:05:04,242 INFO: Microblog startup [in /home/nagianek/PycharmProjects/Flask-Microblog/venv/app/__init__.py:78]
2018-05-15 15:06:51,654 INFO: Microblog startup [in /home/nagianek/PycharmProjects/Flask-Microblog/venv/app/__init__.py:78]
2018-05-15 20:08:16,597 INFO: Microblog startup [in /home/nagianek/PycharmProjects/Flask-Microblog/venv/app/__init__.py:82]
2018-05-15 20:08:37,797 ERROR: Exception on /search [GET] [in /home/nagianek/.local/lib/python3.6/site-packages/flask/app.py:1560]
Traceback (most recent call last):
  File "/home/nagianek/.local/lib/python3.6/site-packages/flask/app.py", line 1982, in wsgi_app
    response = self.full_dispatch_request()
  File "/home/nagianek/.local/lib/python3.6/site-packages/flask/app.py", line 1614, in full_dispatch_request
    rv = self.handle_user_exception(e)
  File "/home/nagianek/.local/lib/python3.6/site-packages/flask/app.py", line 1517, in handle_user_exception
    reraise(exc_type, exc_value, tb)
  File "/home/nagianek/.local/lib/python3.6/site-packages/flask/_compat.py", line 33, in reraise
    raise value
  File "/home/nagianek/.local/lib/python3.6/site-packages/flask/app.py", line 1612, in full_dispatch_request
    rv = self.dispatch_request()
  File "/home/nagianek/.local/lib/python3.6/site-packages/flask/app.py", line 1598, in dispatch_request
    return self.view_functions[rule.endpoint](**req.view_args)
  File "/home/nagianek/.local/lib/python3.6/site-packages/flask_login/utils.py", line 228, in decorated_view
    return func(*args, **kwargs)
  File "/home/nagianek/PycharmProjects/Flask-Microblog/venv/app/main/routes.py", line 146, in search
    current_app.config['POSTS_PER_PAGE'])
  File "/home/nagianek/PycharmProjects/Flask-Microblog/venv/app/models.py", line 16, in search
    ids, total = query_index(cls.__tablename__, expression, page, per_page)
  File "/home/nagianek/PycharmProjects/Flask-Microblog/venv/app/search.py", line 23, in query_index
    'from': (page - 1) * per_page, 'size': per_page})
  File "/home/nagianek/.local/lib/python3.6/site-packages/elasticsearch/client/utils.py", line 76, in _wrapped
    return func(*args, params=params, **kwargs)
  File "/home/nagianek/.local/lib/python3.6/site-packages/elasticsearch/client/__init__.py", line 655, in search
    doc_type, '_search'), params=params, body=body)
  File "/home/nagianek/.local/lib/python3.6/site-packages/elasticsearch/transport.py", line 314, in perform_request
    status, headers_response, data = connection.perform_request(method, url, params, body, headers=headers, ignore=ignore, timeout=timeout)
  File "/home/nagianek/.local/lib/python3.6/site-packages/elasticsearch/connection/http_urllib3.py", line 180, in perform_request
    self._raise_error(response.status, raw_data)
  File "/home/nagianek/.local/lib/python3.6/site-packages/elasticsearch/connection/base.py", line 125, in _raise_error
    raise HTTP_EXCEPTIONS.get(status_code, TransportError)(status_code, error_message, additional_info)
elasticsearch.exceptions.NotFoundError: TransportError(404, 'index_not_found_exception', 'no such index')
2018-05-15 20:10:14,620 INFO: Microblog startup [in /home/nagianek/PycharmProjects/Flask-Microblog/venv/app/__init__.py:82]
2018-05-15 20:10:39,645 INFO: Microblog startup [in /home/nagianek/PycharmProjects/Flask-Microblog/venv/app/__init__.py:82]
