2018-05-15 14:03:27,671 ERROR: Exception on /index [GET] [in /home/nagianek/.local/lib/python3.6/site-packages/flask/app.py:1560]
Traceback (most recent call last):
  File "/home/nagianek/.local/lib/python3.6/site-packages/flask/app.py", line 1982, in wsgi_app
    response = self.full_dispatch_request()
  File "/home/nagianek/.local/lib/python3.6/site-packages/flask/app.py", line 1614, in full_dispatch_request
    rv = self.handle_user_exception(e)
  File "/home/nagianek/.local/lib/python3.6/site-packages/flask/app.py", line 1517, in handle_user_exception
    reraise(exc_type, exc_value, tb)
  File "/home/nagianek/.local/lib/python3.6/site-packages/flask/_compat.py", line 33, in reraise
    raise value
  File "/home/nagianek/.local/lib/python3.6/site-packages/flask/app.py", line 1610, in full_dispatch_request
    rv = self.preprocess_request()
  File "/home/nagianek/.local/lib/python3.6/site-packages/flask/app.py", line 1831, in preprocess_request
    rv = func()
  File "/home/nagianek/PycharmProjects/Flask-Microblog/venv/app/routes.py", line 123, in before_request
    g.locale = str(get_locale())
  File "/home/nagianek/.local/lib/python3.6/site-packages/flask_babel/__init__.py", line 253, in get_locale
    babel = current_app.extensions['babel']
KeyError: 'babel'
2018-05-15 14:03:27,807 ERROR: Exception on /favicon.ico [GET] [in /home/nagianek/.local/lib/python3.6/site-packages/flask/app.py:1560]
Traceback (most recent call last):
  File "/home/nagianek/.local/lib/python3.6/site-packages/flask/app.py", line 1982, in wsgi_app
    response = self.full_dispatch_request()
  File "/home/nagianek/.local/lib/python3.6/site-packages/flask/app.py", line 1614, in full_dispatch_request
    rv = self.handle_user_exception(e)
  File "/home/nagianek/.local/lib/python3.6/site-packages/flask/app.py", line 1517, in handle_user_exception
    reraise(exc_type, exc_value, tb)
  File "/home/nagianek/.local/lib/python3.6/site-packages/flask/_compat.py", line 33, in reraise
    raise value
  File "/home/nagianek/.local/lib/python3.6/site-packages/flask/app.py", line 1610, in full_dispatch_request
    rv = self.preprocess_request()
  File "/home/nagianek/.local/lib/python3.6/site-packages/flask/app.py", line 1831, in preprocess_request
    rv = func()
  File "/home/nagianek/PycharmProjects/Flask-Microblog/venv/app/routes.py", line 123, in before_request
    g.locale = str(get_locale())
  File "/home/nagianek/.local/lib/python3.6/site-packages/flask_babel/__init__.py", line 253, in get_locale
    babel = current_app.extensions['babel']
KeyError: 'babel'
2018-05-15 14:04:50,569 INFO: Microblog startup [in /home/nagianek/PycharmProjects/Flask-Microblog/venv/app/__init__.py:43]
2018-05-15 14:04:52,318 ERROR: Exception on /index [GET] [in /home/nagianek/.local/lib/python3.6/site-packages/flask/app.py:1560]
Traceback (most recent call last):
  File "/home/nagianek/.local/lib/python3.6/site-packages/flask/app.py", line 1982, in wsgi_app
    response = self.full_dispatch_request()
  File "/home/nagianek/.local/lib/python3.6/site-packages/flask/app.py", line 1614, in full_dispatch_request
    rv = self.handle_user_exception(e)
  File "/home/nagianek/.local/lib/python3.6/site-packages/flask/app.py", line 1517, in handle_user_exception
    reraise(exc_type, exc_value, tb)
  File "/home/nagianek/.local/lib/python3.6/site-packages/flask/_compat.py", line 33, in reraise
    raise value
  File "/home/nagianek/.local/lib/python3.6/site-packages/flask/app.py", line 1610, in full_dispatch_request
    rv = self.preprocess_request()
  File "/home/nagianek/.local/lib/python3.6/site-packages/flask/app.py", line 1831, in preprocess_request
    rv = func()
  File "/home/nagianek/PycharmProjects/Flask-Microblog/venv/app/routes.py", line 123, in before_request
    g.locale = str(get_locale())
  File "/home/nagianek/.local/lib/python3.6/site-packages/flask_babel/__init__.py", line 253, in get_locale
    babel = current_app.extensions['babel']
KeyError: 'babel'
2018-05-15 14:04:52,457 ERROR: Exception on /favicon.ico [GET] [in /home/nagianek/.local/lib/python3.6/site-packages/flask/app.py:1560]
Traceback (most recent call last):
  File "/home/nagianek/.local/lib/python3.6/site-packages/flask/app.py", line 1982, in wsgi_app
    response = self.full_dispatch_request()
  File "/home/nagianek/.local/lib/python3.6/site-packages/flask/app.py", line 1614, in full_dispatch_request
    rv = self.handle_user_exception(e)
  File "/home/nagianek/.local/lib/python3.6/site-packages/flask/app.py", line 1517, in handle_user_exception
    reraise(exc_type, exc_value, tb)
  File "/home/nagianek/.local/lib/python3.6/site-packages/flask/_compat.py", line 33, in reraise
    raise value
  File "/home/nagianek/.local/lib/python3.6/site-packages/flask/app.py", line 1610, in full_dispatch_request
    rv = self.preprocess_request()
  File "/home/nagianek/.local/lib/python3.6/site-packages/flask/app.py", line 1831, in preprocess_request
    rv = func()
  File "/home/nagianek/PycharmProjects/Flask-Microblog/venv/app/routes.py", line 123, in before_request
    g.locale = str(get_locale())
  File "/home/nagianek/.local/lib/python3.6/site-packages/flask_babel/__init__.py", line 253, in get_locale
    babel = current_app.extensions['babel']
KeyError: 'babel'
2018-05-15 14:06:37,955 INFO: Microblog startup [in /home/nagianek/PycharmProjects/Flask-Microblog/venv/app/__init__.py:43]
2018-05-15 14:06:41,406 ERROR: Exception on /index [GET] [in /home/nagianek/.local/lib/python3.6/site-packages/flask/app.py:1560]
Traceback (most recent call last):
  File "/home/nagianek/.local/lib/python3.6/site-packages/flask/app.py", line 1982, in wsgi_app
    response = self.full_dispatch_request()
  File "/home/nagianek/.local/lib/python3.6/site-packages/flask/app.py", line 1614, in full_dispatch_request
    rv = self.handle_user_exception(e)
  File "/home/nagianek/.local/lib/python3.6/site-packages/flask/app.py", line 1517, in handle_user_exception
    reraise(exc_type, exc_value, tb)
  File "/home/nagianek/.local/lib/python3.6/site-packages/flask/_compat.py", line 33, in reraise
    raise value
  File "/home/nagianek/.local/lib/python3.6/site-packages/flask/app.py", line 1610, in full_dispatch_request
    rv = self.preprocess_request()
  File "/home/nagianek/.local/lib/python3.6/site-packages/flask/app.py", line 1831, in preprocess_request
    rv = func()
  File "/home/nagianek/PycharmProjects/Flask-Microblog/venv/app/routes.py", line 123, in before_request
    g.locale = str(get_locale())
  File "/home/nagianek/.local/lib/python3.6/site-packages/flask_babel/__init__.py", line 253, in get_locale
    babel = current_app.extensions['babel']
KeyError: 'babel'
2018-05-15 14:06:41,547 ERROR: Exception on /favicon.ico [GET] [in /home/nagianek/.local/lib/python3.6/site-packages/flask/app.py:1560]
Traceback (most recent call last):
  File "/home/nagianek/.local/lib/python3.6/site-packages/flask/app.py", line 1982, in wsgi_app
    response = self.full_dispatch_request()
  File "/home/nagianek/.local/lib/python3.6/site-packages/flask/app.py", line 1614, in full_dispatch_request
    rv = self.handle_user_exception(e)
  File "/home/nagianek/.local/lib/python3.6/site-packages/flask/app.py", line 1517, in handle_user_exception
    reraise(exc_type, exc_value, tb)
  File "/home/nagianek/.local/lib/python3.6/site-packages/flask/_compat.py", line 33, in reraise
    raise value
  File "/home/nagianek/.local/lib/python3.6/site-packages/flask/app.py", line 1610, in full_dispatch_request
    rv = self.preprocess_request()
  File "/home/nagianek/.local/lib/python3.6/site-packages/flask/app.py", line 1831, in preprocess_request
    rv = func()
  File "/home/nagianek/PycharmProjects/Flask-Microblog/venv/app/routes.py", line 123, in before_request
    g.locale = str(get_locale())
  File "/home/nagianek/.local/lib/python3.6/site-packages/flask_babel/__init__.py", line 253, in get_locale
    babel = current_app.extensions['babel']
KeyError: 'babel'
2018-05-15 14:06:42,255 ERROR: Exception on /index [GET] [in /home/nagianek/.local/lib/python3.6/site-packages/flask/app.py:1560]
Traceback (most recent call last):
  File "/home/nagianek/.local/lib/python3.6/site-packages/flask/app.py", line 1982, in wsgi_app
    response = self.full_dispatch_request()
  File "/home/nagianek/.local/lib/python3.6/site-packages/flask/app.py", line 1614, in full_dispatch_request
    rv = self.handle_user_exception(e)
  File "/home/nagianek/.local/lib/python3.6/site-packages/flask/app.py", line 1517, in handle_user_exception
    reraise(exc_type, exc_value, tb)
  File "/home/nagianek/.local/lib/python3.6/site-packages/flask/_compat.py", line 33, in reraise
    raise value
  File "/home/nagianek/.local/lib/python3.6/site-packages/flask/app.py", line 1610, in full_dispatch_request
    rv = self.preprocess_request()
  File "/home/nagianek/.local/lib/python3.6/site-packages/flask/app.py", line 1831, in preprocess_request
    rv = func()
  File "/home/nagianek/PycharmProjects/Flask-Microblog/venv/app/routes.py", line 123, in before_request
    g.locale = str(get_locale())
  File "/home/nagianek/.local/lib/python3.6/site-packages/flask_babel/__init__.py", line 253, in get_locale
    babel = current_app.extensions['babel']
KeyError: 'babel'
